<?xml version="1.0" ?>
<!-- =================================================================================== -->
<!-- |    This document was autogenerated by xacro from scara.xacro                    | -->
<!-- |    EDITING THIS FILE BY HAND IS NOT RECOMMENDED                                 | -->
<!-- =================================================================================== -->
<!-- RRP Manipulator -->
<robot name="scara">
  <!-- Space btw top of beam and the each joint -->
  <gazebo>
    <plugin filename="libgazebo_ros_joint_state_publisher.so" name="joint_state_publisher">
      <jointName>joint1, joint2, joint3</jointName>
    </plugin>
  </gazebo>
  <gazebo>
    <plugin filename="libgazebo_ros_control.so" name="gazebo_ros_control">
      <robotNamespace>/scara</robotNamespace>
    </plugin>
  </gazebo>
  <!-- Link1 -->
  <gazebo reference="link1">
    <mu1>0.2</mu1>
    <mu2>0.2</mu2>
    <material>Gazebo/Orange</material>
  </gazebo>
  <!-- Link2 -->
  <gazebo reference="link2">
    <mu1>0.2</mu1>
    <mu2>0.2</mu2>
    <material>Gazebo/Orange</material>
  </gazebo>
  <!-- Link3 -->
  <gazebo reference="link3">
    <mu1>0.2</mu1>
    <mu2>0.2</mu2>
    <material>Gazebo/Orange</material>
  </gazebo>
  <material name="black">
    <color rgba="0.0 0.0 0.0 1.0"/>
  </material>
  <material name="blue">
    <color rgba="0.0 0.0 0.8 1.0"/>
  </material>
  <material name="green">
    <color rgba="0.0 0.8 0.0 1.0"/>
  </material>
  <material name="grey">
    <color rgba="0.2 0.2 0.2 1.0"/>
  </material>
  <material name="orange">
    <color rgba="1.0 0.4235294117647059 0.0392156862745098 1.0"/>
  </material>
  <material name="brown">
    <color rgba="0.8705882352941177 0.8117647058823529 0.7647058823529411 1.0"/>
  </material>
  <material name="red">
    <color rgba="0.8 0.0 0.0 1.0"/>
  </material>
  <material name="white">
    <color rgba="1.0 1.0 1.0 1.0"/>
  </material>
  <!-- Used for fixing robot to Gazebo 'base_link' -->
  <link name="world"/>
  <!-- Base Rev Joint1 -->
  <joint name="joint1" type="revolute">
    <parent link="world"/>
    <child link="link1"/>
    <origin rpy="0 0 0" xyz="0 0 0"/>
    <axis xyz="0 0 1"/>
    <limit effort="30" lower="-1.5707963267948966" upper="1.5707963267948966" velocity="1.0"/>
    <dynamics damping="0.7"/>
  </joint>
  <!-- Base Link -->
  <link name="link1">
    <collision>
      <origin rpy="0 0 0" xyz="0 0 0.25"/>
      <geometry>
        <box size="0.1 0.1 0.5"/>
      </geometry>
    </collision>
    <visual>
      <origin rpy="0 0 0" xyz="0 0 0.25"/>
      <geometry>
        <box size="0.1 0.1 0.5"/>
      </geometry>
      <material name="orange"/>
    </visual>
    <inertial>
      <origin rpy="0 0 0" xyz="0 0 0.25"/>
      <mass value="0.2"/>
      <inertia ixx="0.004333333333333333" ixy="0.0" ixz="0.0" iyx="0.0" iyy="0.004333333333333333" iyz="0.0" izx="0.0" izy="0.0" izz="0.0003333333333333334"/>
    </inertial>
  </link>
  <!-- For offset link -->
  <joint name="joint1_offset" type="fixed">
    <parent link="link1"/>
    <child link="link1_offset"/>
    <origin rpy="0 0 0" xyz="0 0 0.55"/>
  </joint>
  <!-- Offset Link -->
  <link name="link1_offset">
    <collision>
      <origin rpy="0 1.5707963267948966 0" xyz="0.075 0 0"/>
      <geometry>
        <box size="0.1 0.1 0.25"/>
      </geometry>
    </collision>
    <visual>
      <origin rpy="0 1.5707963267948966 0" xyz="0.075 0 0"/>
      <geometry>
        <box size="0.1 0.1 0.25"/>
      </geometry>
      <material name="orange"/>
    </visual>
    <inertial>
      <origin rpy="0 1.5707963267948966 0" xyz="0.075 0 0"/>
      <mass value="0.2"/>
      <inertia ixx="0.0012083333333333334" ixy="0.0" ixz="0.0" iyx="0.0" iyy="0.0012083333333333334" iyz="0.0" izx="0.0" izy="0.0" izz="0.0003333333333333334"/>
    </inertial>
  </link>
  <!-- Middle Rev Joint2 -->
  <joint name="joint2" type="revolute">
    <parent link="link1_offset"/>
    <child link="link2"/>
    <origin rpy="0 0 0" xyz="0.15 0 0.1"/>
    <axis xyz="0 0 1"/>
    <limit effort="30" lower="-1.5707963267948966" upper="1.5707963267948966" velocity="1.0"/>
    <dynamics damping="0.7"/>
  </joint>
  <!-- Middle Link -->
  <link name="link2">
    <collision>
      <origin rpy="0 1.5707963267948966 0" xyz="0.12499999999999999 0 0"/>
      <geometry>
        <box size="0.1 0.1 0.35"/>
      </geometry>
    </collision>
    <visual>
      <origin rpy="0 1.5707963267948966 0" xyz="0.12499999999999999 0 0"/>
      <geometry>
        <box size="0.1 0.1 0.35"/>
      </geometry>
      <material name="orange"/>
    </visual>
    <inertial>
      <origin rpy="0 1.5707963267948966 0" xyz="0.12499999999999999 0 0"/>
      <mass value="0.2"/>
      <inertia ixx="0.002208333333333333" ixy="0.0" ixz="0.0" iyx="0.0" iyy="0.002208333333333333" iyz="0.0" izx="0.0" izy="0.0" izz="0.0003333333333333334"/>
    </inertial>
  </link>
  <!-- Final Prismatic Joint3 -->
  <joint name="joint3" type="prismatic">
    <parent link="link2"/>
    <child link="link3"/>
    <origin rpy="0 3.141592653589793 0" xyz="0.35 0 0"/>
    <!-- Limits are from the link origin and not the joint origins -->
    <limit effort="100" lower="0" upper="0.175" velocity="1.0"/>
    <axis xyz="0 0 1"/>
    <dynamics damping="0.7"/>
  </joint>
  <!-- Final Link -->
  <link name="link3">
    <collision>
      <origin rpy="0 0 0" xyz="0 0 -0.175"/>
      <geometry>
        <box size="0.1 0.1 0.25"/>
      </geometry>
    </collision>
    <visual>
      <origin rpy="0 0 0" xyz="0 0 -0.175"/>
      <geometry>
        <box size="0.1 0.1 0.25"/>
      </geometry>
      <material name="orange"/>
    </visual>
    <inertial>
      <origin rpy="0 0 0" xyz="0 0 -0.175"/>
      <mass value="0.1"/>
      <inertia ixx="0.0006041666666666667" ixy="0.0" ixz="0.0" iyx="0.0" iyy="0.0006041666666666667" iyz="0.0" izx="0.0" izy="0.0" izz="0.0001666666666666667"/>
    </inertial>
  </link>
  <transmission name="tran1">
    <type>transmission_interface/SimpleTransmission</type>
    <joint name="joint1">
      <!--hardwareInterface>hardware_interface/EffortJointInterface</hardwareInterface-->
      <hardwareInterface>hardware_interface/VelocityJointInterface</hardwareInterface>
    </joint>
    <actuator name="motor1">
      <!--hardwareInterface>hardware_interface/EffortJointInterface</hardwareInterface-->
      <hardwareInterface>hardware_interface/VelocityJointInterface</hardwareInterface>
      <mechanicalReduction>1</mechanicalReduction>
    </actuator>
  </transmission>
  <transmission name="tran2">
    <type>transmission_interface/SimpleTransmission</type>
    <joint name="joint2">
      <!--hardwareInterface>hardware_interface/EffortJointInterface</hardwareInterface-->
      <hardwareInterface>hardware_interface/VelocityJointInterface</hardwareInterface>
    </joint>
    <actuator name="motor2">
      <!--hardwareInterface>hardware_interface/EffortJointInterface</hardwareInterface-->
      <hardwareInterface>hardware_interface/VelocityJointInterface</hardwareInterface>
      <mechanicalReduction>1</mechanicalReduction>
    </actuator>
  </transmission>
  <transmission name="tran3">
    <type>transmission_interface/SimpleTransmission</type>
    <joint name="joint3">
      <!--hardwareInterface>hardware_interface/EffortJointInterface</hardwareInterface-->
      <hardwareInterface>hardware_interface/VelocityJointInterface</hardwareInterface>
    </joint>
    <actuator name="motor3">
      <!--hardwareInterface>hardware_interface/EffortJointInterface</hardwareInterface-->
      <hardwareInterface>hardware_interface/VelocityJointInterface</hardwareInterface>
      <mechanicalReduction>1</mechanicalReduction>
    </actuator>
  </transmission>
</robot>

